Workbook

Sheet Identificación e Instrucciones
A1: Datos del proyecto
A2: Cliente:
A3: Nombre del proyecto:
A4: Gerente de cuenta:
A5: Coordinador:
A6: Fecha de inicio:
A7: Tipo de proyecto:
A8: Tamaño de proyecto:
A10: Instrucciones comunes a todas las pestañas
A11: * Lo verde debe diligenciarse, lo rojo es calculado, lo azul son títulos
A12: * Añadir las columnas necesarias de acuerdo a la duración del proyecto, teniendo cuidado de actualizar los cálculos de totales rojos
A13: * En cada mes debe diligenciarse el porcentaje de dedicación de cada recurso y el salario para ese mes (El porcentaje para "A cobrar" se hace suponiendo meses de 20 días hábiles)
... A33: Manejo de horas extras: en caso de que haya horas extras de algún rol/persona, deberá meterse una línea adicional en personas. Es decir, se mete como si fuera un recurso aparte

Sheet Iteraciones
A2: Total Esfuerzo en Horas | B2: =97-20 -> 77
A3: Desarrollo | H3: Tiempos calculados | AA3: S
A4: Esfuerzo (días/hombre) estimado de desarrollo: | F4: =B2/8 -> 9.625 | H4: Tiempo ajustado total de desarrollo x velocity (días/ingeniero) | N4: =CEILING(F4*(8/F6),1) -> 20 | P4: Total Esfuerzo Basado en Dias de 8 Horas | S4: Total de esfuerzo en horas | AA4: N
A5: Dedicación de ingenieros de desarrollo: | F5: 1 | H5: Duración de desarrollo con equipo asignado: | N5: =CEILING(N4/F5,1) -> 20
A6: Velocity promedio (en horas) por persona/día: | F6: 4 | H6: Duración de desarrollo del Iteración 1: | N6: =CEILING((N5/F9)+F10,1) -> 20 | P6: =F4+((F7+F8+F10)*F9)+F13+F14+F15+F16+F17 -> 12.125 | S6: =P6*8 -> 97
A7: Días de planeación por iteración: | F7: 0 | H7: =IF(F9>1, CONCATENATE("Duración de desarrollo de los Iteración 2 a ",F9,":"),"Duración Iteración 2 en adelante") -> Duración Iteración 2 en adelante | N7: =IF(F9>1,CEILING( (N5/F9),1),0) -> 0
A8: Días de presentación por Iteración: | F8: 0 | H8: Duración total de Iteración 1 (incluye planeación y presentación): | N8: =CEILING( N6+F7+F8,1) -> 20
A9: Número de Iteraciones: | F9: 1 | H9: =IF(F9>1, CONCATENATE("Duración total de los Iteración 2 a ",F9," (incluye planeación y presentación):"),"Duración Iteración 2 en adelante (incluye planeación y presentación)") -> Duración Iteración 2 en adelante (incluye planeación y presentación) | N9: =IF(F9>1, CEILING( N7+F7+F8,1),0) -> 0
A10: Días adicionales Iteración 1 | F10: 0 | L10: Total días desarrollo | N10: =((N8+(N9*(F9-1)))) -> 20
A12: Pre y post desarrollo | H12: =CONCATENATE("Tiempo total con ",F9," Iteraciones") -> Tiempo total con 1 Iteraciones
A13: Preparación equipo y ambientes de desarrollo: | F13: 0.5 | H13: =CONCATENATE(N10+F14+F15+F16+F17+F13, " días") -> 22.5 días | K13: <-- Incluye Días preparación equipo, Exploración del negocio, desarrollo, estabilización, instalación y acompañamiento
A14: Días de exploración del negocio: | F14: 0 | H14: =CONCATENATE((N10+F14+F15+F16+F17+F13)/20, " meses") -> 1.125 meses
A15: Días de documentación, pruebas integrales y estabilización: | F15: 1 | H15: =((N10+F14+F15+F16+F17+F13)/20) -> 1.125 | K15: <-- Este es el porcentaje total de dedicación del rol que más tiempo dure, desde el primero al último día de proyecto
A16: Dias de instalación: | F16: 0.5
A17: Días de acompañamiento: | F17: 0.5
A19: Notas importantes:
A20: - El tiempo calculado corresponde al equipo de desarrollo. Los tiempos de roles como Scrum Master, Tracker, Pruebas y Diseño deben calcularse manualmente de acuerdo a la dedicación que vayan a tener
A21: - Los tiempos de exploración del negocio, estabilización, instalación y acompañamiento no se calculan automáticamente. Deben registrarse manualmente y la dedicación de cada rol también se calcula manualmente
A23: Formato resumen para presentar en la propuesta:
H24: Equipo de trabajo y dedicación por fases
A25: Fases y duraciones del proyecto (días hábiles) | H25: Fase | L25: Equipo asignado
A26: Preparación de equipo y ambientes | F26: =F13 -> 0.5 | H26: =A26 -> Preparación de equipo y ambientes
A27: Exploración del negocio | F27: =F14 -> 0 | H27: =A27 -> Exploración del negocio
A28: =CONCATENATE("Desarrollo del sistema - (",F9,") Iteraci",IF(F9>1,"ones","ón")) -> Desarrollo del sistema - (1) Iteración | F28: =N10 -> 20 | H28: =A28 -> Desarrollo del sistema - (1) Iteración
A29: Documentación, pruebas integrales y estabilización | F29: =F15 -> 1 | H29: =A29 -> Documentación, pruebas integrales y estabilización
A30: Instalación | F30: =F16 -> 0.5 | H30: =A30 -> Instalación
A31: Acompañamiento en producción | F31: =F17 -> 0.5 | H31: =A31 -> Acompañamiento en producción
A32: TOTAL PROYECTO (Días hábiles) | F32: =SUM(F26:F31) -> 22.5
A33: Meses | F33: =F32/20 -> 1.125
H34: Iteraciones que son Release e/o Hito de facturación
H35: # Iteración | I35: Release | J35: Hito | K35: Observaciones

Sheet A cobrar
D1: Mes 1 | E1: Mes 2 | F1: Mes 3 | G1: Mes 4 | H1: Mes 5 | I1: Mes 6 | J1: Mes 7 | K1: Mes 8 | L1: Mes 9 | M1: Mes 10 | N1: Mes 11 | O1: Mes 12 | P1: Mes 13 | Q1: Mes 14 | R1: Mes 15 | S1: Mes 16 | T1: Mes 17 | U1: Mes 18
A2: Personal | B2: =+C5+C8+C11+C14+C17+C20+C23+C29+C26+C32+C35+C38+C41+C44+C47 -> 7978250 | C2: Totales | D2: =+D5+D8+D11+D14+D17+D20+D23+D29+D26+D32+D35+D38+D41+D44+D47 -> 7978250 | E2: =+E5+E8+E11+E14+E17+E20+E23+E29+E26+E32+E35+E38+E41+E44+E47 -> 0 | F2: =+F5+F8+F11+F14+F17+F20+F23+F29+F26+F32+F35+F38+F41+F44+F47 -> 0 | G2: =+G5+G8+G11+G14+G17+G20+G23+G29+G26+G32+G35+G38+G41+G44+G47 -> 0 | H2: =+H5+H8+H11+H14+H17+H20+H23+H29+H26+H32+H35+H38+H41+H44+H47 -> 0 | I2: =+I5+I8+I11+I14+I17+I20+I23+I29+I26+I32+I35+I38+I41+I44+I47 -> 0 | J2: =+J5+J8+J11+J14+J17+J20+J23+J29+J26+J32+J35+J38+J41+J44+J47 -> 0 | K2: =+K5+K8+K11+K14+K17+K20+K23+K29+K26+K32+K35+K38+K41+K44+K47 -> 0 | ... U2: =+U5+U8+U11+U14+U17+U20+U23+U29+U26+U32+U35+U38+U41+U44+U47 -> 0
A3: Senior Developer/Arquitecto (Javier) | B3: Valor mensual | D3: 16000000
B4: Dedicación | C4: =C5/D3 -> 0.0303125 | D4: 0.05
C5: =SUM(D5:U5) -> 485000 | D5: =(D4*D3)*(MIN(MAX(Iteraciones!$P$6-20*(COLUMN()-COLUMN($D5)),0),20)/20) -> 485000 | E5: =(E4*E3)*(MIN(MAX(Iteraciones!$P$6-20*(COLUMN()-COLUMN($D5)),0),20)/20) -> 0 | F5: =(F4*F3)*(MIN(MAX(Iteraciones!$P$6-22*(COLUMN()-COLUMN($D5)),0),22)/22) -> 0 | G5: =(G4*G3)*(MIN(MAX(Iteraciones!$P$6-22*(COLUMN()-COLUMN($D5)),0),22)/22) -> 0 | H5: =(H4*H3)*(MIN(MAX(Iteraciones!$P$6-22*(COLUMN()-COLUMN($D5)),0),22)/22) -> 0 | I5: =(I4*I3)*(MIN(MAX(Iteraciones!$P$6-22*(COLUMN()-COLUMN($D5)),0),22)/22) -> 0 | J5: =(J4*J3)*(MIN(MAX(Iteraciones!$P$6-22*(COLUMN()-COLUMN($D5)),0),22)/22) -> 0 | K5: =(K4*K3)*(MIN(MAX(Iteraciones!$P$6-22*(COLUMN()-COLUMN($D5)),0),22)/22) -> 0 | L5: =(L4*L3)*(MIN(MAX(Iteraciones!$P$6-22*(COLUMN()-COLUMN($D5)),0),22)/22) -> 0 | M5: =(M4*M3)*(MIN(MAX(Iteraciones!$P$6-22*(COLUMN()-COLUMN($D5)),0),22)/22) -> 0 | ... P5: =(P4*P3)*(MIN(MAX(Iteraciones!$P$6-22*(COLUMN()-COLUMN($D5)),0),22)/22) -> 0 | Q5: =Q4*Q3 -> 0 | R5: =R4*R3 -> 0 | S5: =S4*S3 -> 0 | T5: =T4*T3 -> 0 | U5: =U4*U3 -> 0
A6: Senior Developer (Andres) | B6: Valor mensual | D6: 14500000
B7: Dedicación | C7: =C8/D6 -> 0.485 | D7: 0.8
C8: =SUM(D8:U8) -> 7032500 | D8: =(D7*D6)*(MIN(MAX(Iteraciones!$P$6-20*(COLUMN()-COLUMN($D8)),0),20)/20) -> 7032500 | E8: =(E7*E6)*(MIN(MAX(Iteraciones!$P$6-20*(COLUMN()-COLUMN($D8)),0),20)/20) -> 0 | F8: =(F7*F6)*(MIN(MAX(Iteraciones!$P$6-22*(COLUMN()-COLUMN($D8)),0),22)/22) -> 0 | G8: =(G7*G6)*(MIN(MAX(Iteraciones!$P$6-22*(COLUMN()-COLUMN($D8)),0),22)/22) -> 0 | H8: =(H7*H6)*(MIN(MAX(Iteraciones!$P$6-22*(COLUMN()-COLUMN($D8)),0),22)/22) -> 0 | I8: =(I7*I6)*(MIN(MAX(Iteraciones!$P$6-22*(COLUMN()-COLUMN($D8)),0),22)/22) -> 0 | J8: =(J7*J6)*(MIN(MAX(Iteraciones!$P$6-22*(COLUMN()-COLUMN($D8)),0),22)/22) -> 0 | K8: =(K7*K6)*(MIN(MAX(Iteraciones!$P$6-22*(COLUMN()-COLUMN($D8)),0),22)/22) -> 0 | L8: =(L7*L6)*(MIN(MAX(Iteraciones!$P$6-22*(COLUMN()-COLUMN($D8)),0),22)/22) -> 0 | M8: =(M7*M6)*(MIN(MAX(Iteraciones!$P$6-22*(COLUMN()-COLUMN($D8)),0),22)/22) -> 0 | N8: =(N7*N6)*(MIN(MAX(Iteraciones!$P$6-22*(COLUMN()-COLUMN($D8)),0),22)/22) -> 0 | O8: =O7*O6 -> 0 | P8: =P7*P6 -> 0 | Q8: =Q7*Q6 -> 0 | R8: =R7*R6 -> 0 | S8: =S7*S6 -> 0 | T8: =T7*T6 -> 0 | U8: =U7*U6 -> 0
A9: Analista de pruebas | B9: Valor mensual | D9: 5000000
B10: Dedicación | C10: =C11/D9 -> 0.060625 | D10: 0.1
C11: =SUM(D11:U11) -> 303125 | D11: =(D10*D9)*(MIN(MAX(Iteraciones!$P$6-20*(COLUMN()-COLUMN($D11)),0),20)/20) -> 303125 | E11: =(E10*E9)*(MIN(MAX(Iteraciones!$P$6-20*(COLUMN()-COLUMN($D11)),0),20)/20) -> 0 | F11: =(F10*F9)*(MIN(MAX(Iteraciones!$P$6-22*(COLUMN()-COLUMN($D11)),0),22)/22) -> 0 | G11: =(G10*G9)*(MIN(MAX(Iteraciones!$P$6-22*(COLUMN()-COLUMN($D11)),0),22)/22) -> 0 | H11: =(H10*H9)*(MIN(MAX(Iteraciones!$P$6-22*(COLUMN()-COLUMN($D11)),0),22)/22) -> 0 | I11: =(I10*I9)*(MIN(MAX(Iteraciones!$P$6-22*(COLUMN()-COLUMN($D11)),0),22)/22) -> 0 | J11: =(J10*J9)*(MIN(MAX(Iteraciones!$P$6-22*(COLUMN()-COLUMN($D11)),0),22)/22) -> 0 | K11: =(K10*K9)*(MIN(MAX(Iteraciones!$P$6-22*(COLUMN()-COLUMN($D11)),0),22)/22) -> 0 | L11: =(L10*L9)*(MIN(MAX(Iteraciones!$P$6-22*(COLUMN()-COLUMN($D11)),0),22)/22) -> 0 | M11: =(M10*M9)*(MIN(MAX(Iteraciones!$P$6-22*(COLUMN()-COLUMN($D11)),0),22)/22) -> 0 | N11: =(N10*N9)*(MIN(MAX(Iteraciones!$P$6-22*(COLUMN()-COLUMN($D11)),0),22)/22) -> 0 | O11: =O10*O9 -> 0 | P11: =P10*P9 -> 0 | Q11: =Q10*Q9 -> 0 | R11: =R10*R9 -> 0 | S11: =S10*S9 -> 0 | T11: =T10*T9 -> 0 | U11: =U10*U9 -> 0
A12: Analista funcional | B12: Valor mensual | D12: 6500000
B13: Dedicación | C13: =C14/D12 -> 0.02425 | D13: 0.04
C14: =SUM(D14:U14) -> 157625 | D14: =(D13*D12)*(MIN(MAX(Iteraciones!$P$6-20*(COLUMN()-COLUMN($D14)),0),20)/20) -> 157625 | E14: =(E13*E12)*(MIN(MAX(Iteraciones!$P$6-20*(COLUMN()-COLUMN($D14)),0),20)/20) -> 0 | F14: =(F13*F12)*(MIN(MAX(Iteraciones!$P$6-22*(COLUMN()-COLUMN($D14)),0),22)/22) -> 0 | G14: =(G13*G12)*(MIN(MAX(Iteraciones!$P$6-22*(COLUMN()-COLUMN($D14)),0),22)/22) -> 0 | H14: =(H13*H12)*(MIN(MAX(Iteraciones!$P$6-22*(COLUMN()-COLUMN($D14)),0),22)/22) -> 0 | I14: =(I13*I12)*(MIN(MAX(Iteraciones!$P$6-22*(COLUMN()-COLUMN($D14)),0),22)/22) -> 0 | J14: =(J13*J12)*(MIN(MAX(Iteraciones!$P$6-22*(COLUMN()-COLUMN($D14)),0),22)/22) -> 0 | K14: =(K13*K12)*(MIN(MAX(Iteraciones!$P$6-22*(COLUMN()-COLUMN($D14)),0),22)/22) -> 0 | L14: =(L13*L12)*(MIN(MAX(Iteraciones!$P$6-22*(COLUMN()-COLUMN($D14)),0),22)/22) -> 0 | M14: =(M13*M12)*(MIN(MAX(Iteraciones!$P$6-22*(COLUMN()-COLUMN($D14)),0),22)/22) -> 0 | N14: =(N13*N12)*(MIN(MAX(Iteraciones!$P$6-22*(COLUMN()-COLUMN($D14)),0),22)/22) -> 0 | O14: =O13*O12 -> 0 | P14: =P13*P12 -> 0 | Q14: =Q13*Q12 -> 0 | R14: =R13*R12 -> 0 | S14: =S13*S12 -> 0 | T14: =T13*T12 -> 0 | U14: =U13*U12 -> 0
A15: Rol 5 | B15: Valor mensual
B16: Dedicación | C16: =SUM(D16:U16) -> 0
C17: =SUM(D17:U17) -> 0 | D17: =D16*D15 -> 0 | E17: =E16*E15 -> 0 | F17: =F16*F15 -> 0 | G17: =G16*G15 -> 0 | H17: =H16*H15 -> 0 | I17: =I16*I15 -> 0 | J17: =J16*J15 -> 0 | K17: =K16*K15 -> 0 | ... U17: =U16*U15 -> 0
A18: Rol 6 | B18: Valor mensual
B19: Dedicación | C19: =SUM(D19:U19) -> 0
C20: =SUM(D20:U20) -> 0 | D20: =D19*D18 -> 0 | E20: =E19*E18 -> 0 | F20: =F19*F18 -> 0 | G20: =G19*G18 -> 0 | H20: =H19*H18 -> 0 | I20: =I19*I18 -> 0 | J20: =J19*J18 -> 0 | K20: =K19*K18 -> 0 | ... U20: =U19*U18 -> 0
A21: Rol 7 | B21: Valor mensual
B22: Dedicación | C22: =SUM(D22:U22) -> 0
C23: =SUM(D23:U23) -> 0 | D23: =D22*D21 -> 0 | E23: =E22*E21 -> 0 | F23: =F22*F21 -> 0 | G23: =G22*G21 -> 0 | H23: =H22*H21 -> 0 | I23: =I22*I21 -> 0 | J23: =J22*J21 -> 0 | K23: =K22*K21 -> 0 | ... U23: =U22*U21 -> 0
A24: Rol 8 | B24: Valor mensual
B25: Dedicación | C25: =SUM(D25:U25) -> 0
C26: =SUM(D26:U26) -> 0 | D26: =D25*D24 -> 0 | E26: =E25*E24 -> 0 | F26: =F25*F24 -> 0 | G26: =G25*G24 -> 0 | H26: =H25*H24 -> 0 | I26: =I25*I24 -> 0 | J26: =J25*J24 -> 0 | K26: =K25*K24 -> 0 | ... U26: =U25*U24 -> 0
A27: Rol 9 | B27: Valor mensual
B28: Dedicación | C28: =SUM(D28:U28) -> 0
C29: =SUM(D29:U29) -> 0 | D29: =D28*D27 -> 0 | E29: =E28*E27 -> 0 | F29: =F28*F27 -> 0 | G29: =G28*G27 -> 0 | H29: =H28*H27 -> 0 | I29: =I28*I27 -> 0 | J29: =J28*J27 -> 0 | K29: =K28*K27 -> 0 | ... U29: =U28*U27 -> 0
A30: Rol 10 | B30: Valor mensual
B31: Dedicación | C31: =SUM(D31:U31) -> 0
C32: =SUM(D32:U32) -> 0 | D32: =D31*D30 -> 0 | E32: =E31*E30 -> 0 | F32: =F31*F30 -> 0 | G32: =G31*G30 -> 0 | H32: =H31*H30 -> 0 | I32: =I31*I30 -> 0 | J32: =J31*J30 -> 0 | K32: =K31*K30 -> 0 | ... U32: =U31*U30 -> 0
A33: Rol 11 | B33: Valor mensual
B34: Dedicación | C34: =SUM(D34:U34) -> 0
C35: =SUM(D35:U35) -> 0 | D35: =D34*D33 -> 0 | E35: =E34*E33 -> 0 | F35: =F34*F33 -> 0 | G35: =G34*G33 -> 0 | H35: =H34*H33 -> 0 | I35: =I34*I33 -> 0 | J35: =J34*J33 -> 0 | K35: =K34*K33 -> 0 | ... U35: =U34*U33 -> 0
A36: Rol 12 | B36: Valor mensual
B37: Dedicación | C37: =SUM(D37:U37) -> 0
C38: =SUM(D38:U38) -> 0 | D38: =D37*D36 -> 0 | E38: =E37*E36 -> 0 | F38: =F37*F36 -> 0 | G38: =G37*G36 -> 0 | H38: =H37*H36 -> 0 | I38: =I37*I36 -> 0 | J38: =J37*J36 -> 0 | K38: =K37*K36 -> 0 | ... U38: =U37*U36 -> 0
A39: Rol 13 | B39: Valor mensual
B40: Dedicación | C40: =SUM(D40:U40) -> 0
...

Sheet Costos planeados
D1: Mes 1 | E1: Mes 2 | F1: Mes 3 | G1: Mes 4 | H1: Mes 5 | I1: Mes 6 | J1: Mes 7 | K1: Mes 8 | L1: Mes 9 | M1: Mes 10 | N1: Mes 11 | O1: Mes 12 | P1: Mes 13 | Q1: Mes 14 | R1: Mes 15 | S1: Mes 16 | T1: Mes 17 | U1: Mes 18
A2: Personal | B2: =+C5+C8+C11+C14+C17+C20+C23+C29+C26+C32+C35+C38+C41+C44+C47 -> 0 | C2: Totales | D2: =+D5+D8+D11+D14+D17+D20+D23+D29+D26+D32+D35+D38+D41+D44+D47 -> 0 | E2: =+E5+E8+E11+E14+E17+E20+E23+E29+E26+E32+E35+E38+E41+E44+E47 -> 0 | F2: =+F5+F8+F11+F14+F17+F20+F23+F29+F26+F32+F35+F38+F41+F44+F47 -> 0 | G2: =+G5+G8+G11+G14+G17+G20+G23+G29+G26+G32+G35+G38+G41+G44+G47 -> 0 | H2: =+H5+H8+H11+H14+H17+H20+H23+H29+H26+H32+H35+H38+H41+H44+H47 -> 0 | I2: =+I5+I8+I11+I14+I17+I20+I23+I29+I26+I32+I35+I38+I41+I44+I47 -> 0 | J2: =+J5+J8+J11+J14+J17+J20+J23+J29+J26+J32+J35+J38+J41+J44+J47 -> 0 | K2: =+K5+K8+K11+K14+K17+K20+K23+K29+K26+K32+K35+K38+K41+K44+K47 -> 0 | ... U2: =+U5+U8+U11+U14+U17+U20+U23+U29+U26+U32+U35+U38+U41+U44+U47 -> 0
A3: ='A cobrar'!A3 -> Senior Developer/Arquitecto (Javier) | B3: Valor mensual | D3: =$C3*D4 -> 0 | E3: =$C3*E4 -> 0 | F3: =$C3*F4 -> 0 | G3: =$C3*G4 -> 0 | H3: =$C3*H4 -> 0 | I3: =$C3*I4 -> 0 | J3: =$C3*J4 -> 0 | K3: =$C3*K4 -> 0 | ... U3: =$C3*U4 -> 0
B4: Dedicación | C4: =SUM(D4:U4) -> 0.05 | D4: ='A cobrar'!D4 -> 0.05 | E4: ='A cobrar'!E4 -> 0 | F4: ='A cobrar'!F4 -> 0 | G4: ='A cobrar'!G4 -> 0 | H4: ='A cobrar'!H4 -> 0 | I4: ='A cobrar'!I4 -> 0 | J4: ='A cobrar'!J4 -> 0 | K4: ='A cobrar'!K4 -> 0 | ... U4: ='A cobrar'!U4 -> 0
C5: =SUM(D5:U5) -> 0 | D5: =D4*D3 -> 0 | E5: =E4*E3 -> 0 | F5: =F4*F3 -> 0 | G5: =G4*G3 -> 0 | H5: =H4*H3 -> 0 | I5: =I4*I3 -> 0 | J5: =J4*J3 -> 0 | K5: =K4*K3 -> 0 | ... U5: =U4*U3 -> 0
A6: ='A cobrar'!A6 -> Senior Developer (Andres) | B6: Valor mensual | D6: =$C6*D7 -> 0 | E6: =$C6*E7 -> 0 | F6: =$C6*F7 -> 0 | G6: =$C6*G7 -> 0 | H6: =$C6*H7 -> 0 | I6: =$C6*I7 -> 0 | J6: =$C6*J7 -> 0 | K6: =$C6*K7 -> 0 | ... U6: =$C6*U7 -> 0
B7: Dedicación | C7: =SUM(D7:U7) -> 0.8 | D7: ='A cobrar'!D7 -> 0.8 | E7: ='A cobrar'!E7 -> 0 | F7: ='A cobrar'!F7 -> 0 | G7: ='A cobrar'!G7 -> 0 | H7: ='A cobrar'!H7 -> 0 | I7: ='A cobrar'!I7 -> 0 | J7: ='A cobrar'!J7 -> 0 | K7: ='A cobrar'!K7 -> 0 | ... U7: ='A cobrar'!U7 -> 0
C8: =SUM(D8:U8) -> 0 | D8: =D7*D6 -> 0 | E8: =E7*E6 -> 0 | F8: =F7*F6 -> 0 | G8: =G7*G6 -> 0 | H8: =H7*H6 -> 0 | I8: =I7*I6 -> 0 | J8: =J7*J6 -> 0 | K8: =K7*K6 -> 0 | ... U8: =U7*U6 -> 0
A9: ='A cobrar'!A9 -> Analista de pruebas | B9: Salario mensual | D9: =$C9*D10 -> 0 | E9: =$C9*E10 -> 0 | F9: =$C9*F10 -> 0 | G9: =$C9*G10 -> 0 | H9: =$C9*H10 -> 0 | I9: =$C9*I10 -> 0 | J9: =$C9*J10 -> 0 | K9: =$C9*K10 -> 0 | ... U9: =$C9*U10 -> 0
B10: Dedicación | C10: =SUM(D10:U10) -> 0.1 | D10: ='A cobrar'!D10 -> 0.1 | E10: ='A cobrar'!E10 -> 0 | F10: ='A cobrar'!F10 -> 0 | G10: ='A cobrar'!G10 -> 0 | H10: ='A cobrar'!H10 -> 0 | I10: ='A cobrar'!I10 -> 0 | J10: ='A cobrar'!J10 -> 0 | K10: ='A cobrar'!K10 -> 0 | ... U10: ='A cobrar'!U10 -> 0
C11: =SUM(D11:U11) -> 0 | D11: =D10*D9 -> 0 | E11: =E10*E9 -> 0 | F11: =F10*F9 -> 0 | G11: =G10*G9 -> 0 | H11: =H10*H9 -> 0 | I11: =I10*I9 -> 0 | J11: =J10*J9 -> 0 | K11: =K10*K9 -> 0 | ... U11: =U10*U9 -> 0
A12: ='A cobrar'!A12 -> Analista funcional | B12: Salario mensual | D12: =$C12*D13 -> 0 | E12: =$C12*E13 -> 0 | F12: =$C12*F13 -> 0 | G12: =$C12*G13 -> 0 | H12: =$C12*H13 -> 0 | I12: =$C12*I13 -> 0 | J12: =$C12*J13 -> 0 | K12: =$C12*K13 -> 0 | ... U12: =$C12*U13 -> 0
B13: Dedicación | C13: =SUM(D13:U13) -> 0.04 | D13: ='A cobrar'!D13 -> 0.04 | E13: ='A cobrar'!E13 -> 0 | F13: ='A cobrar'!F13 -> 0 | G13: ='A cobrar'!G13 -> 0 | H13: ='A cobrar'!H13 -> 0 | I13: ='A cobrar'!I13 -> 0 | J13: ='A cobrar'!J13 -> 0 | K13: ='A cobrar'!K13 -> 0 | ... U13: ='A cobrar'!U13 -> 0
C14: =SUM(D14:U14) -> 0 | D14: =D13*D12 -> 0 | E14: =E13*E12 -> 0 | F14: =F13*F12 -> 0 | G14: =G13*G12 -> 0 | H14: =H13*H12 -> 0 | I14: =I13*I12 -> 0 | J14: =J13*J12 -> 0 | K14: =K13*K12 -> 0 | ... U14: =U13*U12 -> 0
A15: ='A cobrar'!A15 -> Rol 5 | B15: Salario mensual | D15: =$C15*D16 -> 0 | E15: =$C15*E16 -> 0 | F15: =$C15*F16 -> 0 | G15: =$C15*G16 -> 0 | H15: =$C15*H16 -> 0 | I15: =$C15*I16 -> 0 | J15: =$C15*J16 -> 0 | K15: =$C15*K16 -> 0 | ... U15: =$C15*U16 -> 0
B16: Dedicación | C16: =SUM(D16:U16) -> 0 | D16: ='A cobrar'!D16 -> 0 | E16: ='A cobrar'!E16 -> 0 | F16: ='A cobrar'!F16 -> 0 | G16: ='A cobrar'!G16 -> 0 | H16: ='A cobrar'!H16 -> 0 | I16: ='A cobrar'!I16 -> 0 | J16: ='A cobrar'!J16 -> 0 | K16: ='A cobrar'!K16 -> 0 | ... U16: ='A cobrar'!U16 -> 0
C17: =SUM(D17:U17) -> 0 | D17: =D16*D15 -> 0 | E17: =E16*E15 -> 0 | F17: =F16*F15 -> 0 | G17: =G16*G15 -> 0 | H17: =H16*H15 -> 0 | I17: =I16*I15 -> 0 | J17: =J16*J15 -> 0 | K17: =K16*K15 -> 0 | ... U17: =U16*U15 -> 0
A18: ='A cobrar'!A18 -> Rol 6 | B18: Salario mensual | D18: =$C18*D19 -> 0 | E18: =$C18*E19 -> 0 | F18: =$C18*F19 -> 0 | G18: =$C18*G19 -> 0 | H18: =$C18*H19 -> 0 | I18: =$C18*I19 -> 0 | J18: =$C18*J19 -> 0 | K18: =$C18*K19 -> 0 | ... U18: =$C18*U19 -> 0
B19: Dedicación | C19: =SUM(D19:U19) -> 0 | D19: ='A cobrar'!D19 -> 0 | E19: ='A cobrar'!E19 -> 0 | F19: ='A cobrar'!F19 -> 0 | G19: ='A cobrar'!G19 -> 0 | H19: ='A cobrar'!H19 -> 0 | I19: ='A cobrar'!I19 -> 0 | J19: ='A cobrar'!J19 -> 0 | K19: ='A cobrar'!K19 -> 0 | ... U19: ='A cobrar'!U19 -> 0
C20: =SUM(D20:U20) -> 0 | D20: =D19*D18 -> 0 | E20: =E19*E18 -> 0 | F20: =F19*F18 -> 0 | G20: =G19*G18 -> 0 | H20: =H19*H18 -> 0 | I20: =I19*I18 -> 0 | J20: =J19*J18 -> 0 | K20: =K19*K18 -> 0 | ... U20: =U19*U18 -> 0
A21: ='A cobrar'!A21 -> Rol 7 | B21: Salario mensual | D21: =$C21*D22 -> 0 | E21: =$C21*E22 -> 0 | F21: =$C21*F22 -> 0 | G21: =$C21*G22 -> 0 | H21: =$C21*H22 -> 0 | I21: =$C21*I22 -> 0 | J21: =$C21*J22 -> 0 | K21: =$C21*K22 -> 0 | ... U21: =$C21*U22 -> 0
B22: Dedicación | C22: =SUM(D22:U22) -> 0 | D22: ='A cobrar'!D22 -> 0 | E22: ='A cobrar'!E22 -> 0 | F22: ='A cobrar'!F22 -> 0 | G22: ='A cobrar'!G22 -> 0 | H22: ='A cobrar'!H22 -> 0 | I22: ='A cobrar'!I22 -> 0 | J22: ='A cobrar'!J22 -> 0 | K22: ='A cobrar'!K22 -> 0 | ... U22: ='A cobrar'!U22 -> 0
C23: =SUM(D23:U23) -> 0 | D23: =D22*D21 -> 0 | E23: =E22*E21 -> 0 | F23: =F22*F21 -> 0 | G23: =G22*G21 -> 0 | H23: =H22*H21 -> 0 | I23: =I22*I21 -> 0 | J23: =J22*J21 -> 0 | K23: =K22*K21 -> 0 | ... U23: =U22*U21 -> 0
A24: ='A cobrar'!A24 -> Rol 8 | B24: Salario mensual | D24: =$C24*D25 -> 0 | E24: =$C24*E25 -> 0 | F24: =$C24*F25 -> 0 | G24: =$C24*G25 -> 0 | H24: =$C24*H25 -> 0 | I24: =$C24*I25 -> 0 | J24: =$C24*J25 -> 0 | K24: =$C24*K25 -> 0 | ... U24: =$C24*U25 -> 0
B25: Dedicación | C25: =SUM(D25:U25) -> 0 | D25: ='A cobrar'!D25 -> 0 | E25: ='A cobrar'!E25 -> 0 | F25: ='A cobrar'!F25 -> 0 | G25: ='A cobrar'!G25 -> 0 | H25: ='A cobrar'!H25 -> 0 | I25: ='A cobrar'!I25 -> 0 | J25: ='A cobrar'!J25 -> 0 | K25: ='A cobrar'!K25 -> 0 | ... U25: ='A cobrar'!U25 -> 0
C26: =SUM(D26:U26) -> 0 | D26: =D25*D24 -> 0 | E26: =E25*E24 -> 0 | F26: =F25*F24 -> 0 | G26: =G25*G24 -> 0 | H26: =H25*H24 -> 0 | I26: =I25*I24 -> 0 | J26: =J25*J24 -> 0 | K26: =K25*K24 -> 0 | ... U26: =U25*U24 -> 0
A27: ='A cobrar'!A27 -> Rol 9 | B27: Salario mensual | D27: =$C27*D28 -> 0 | E27: =$C27*E28 -> 0 | F27: =$C27*F28 -> 0 | G27: =$C27*G28 -> 0 | H27: =$C27*H28 -> 0 | I27: =$C27*I28 -> 0 | J27: =$C27*J28 -> 0 | K27: =$C27*K28 -> 0 | ... U27: =$C27*U28 -> 0
B28: Dedicación | C28: =SUM(D28:U28) -> 0 | D28: ='A cobrar'!D28 -> 0 | E28: ='A cobrar'!E28 -> 0 | F28: ='A cobrar'!F28 -> 0 | G28: ='A cobrar'!G28 -> 0 | H28: ='A cobrar'!H28 -> 0 | I28: ='A cobrar'!I28 -> 0 | J28: ='A cobrar'!J28 -> 0 | K28: ='A cobrar'!K28 -> 0 | ... U28: ='A cobrar'!U28 -> 0
C29: =SUM(D29:U29) -> 0 | D29: =D28*D27 -> 0 | E29: =E28*E27 -> 0 | F29: =F28*F27 -> 0 | G29: =G28*G27 -> 0 | H29: =H28*H27 -> 0 | I29: =I28*I27 -> 0 | J29: =J28*J27 -> 0 | K29: =K28*K27 -> 0 | ... U29: =U28*U27 -> 0
A30: ='A cobrar'!A30 -> Rol 10 | B30: Salario mensual | D30: =$C30*D31 -> 0 | E30: =$C30*E31 -> 0 | F30: =$C30*F31 -> 0 | G30: =$C30*G31 -> 0 | H30: =$C30*H31 -> 0 | I30: =$C30*I31 -> 0 | J30: =$C30*J31 -> 0 | K30: =$C30*K31 -> 0 | ... U30: =$C30*U31 -> 0
B31: Dedicación | C31: =SUM(D31:U31) -> 0 | D31: ='A cobrar'!D31 -> 0 | E31: ='A cobrar'!E31 -> 0 | F31: ='A cobrar'!F31 -> 0 | G31: ='A cobrar'!G31 -> 0 | H31: ='A cobrar'!H31 -> 0 | I31: ='A cobrar'!I31 -> 0 | J31: ='A cobrar'!J31 -> 0 | K31: ='A cobrar'!K31 -> 0 | ... U31: ='A cobrar'!U31 -> 0
C32: =SUM(D32:U32) -> 0 | D32: =D31*D30 -> 0 | E32: =E31*E30 -> 0 | F32: =F31*F30 -> 0 | G32: =G31*G30 -> 0 | H32: =H31*H30 -> 0 | I32: =I31*I30 -> 0 | J32: =J31*J30 -> 0 | K32: =K31*K30 -> 0 | ... U32: =U31*U30 -> 0
A33: ='A cobrar'!A33 -> Rol 11 | B33: Salario mensual | D33: =$C33*D34 -> 0 | E33: =$C33*E34 -> 0 | F33: =$C33*F34 -> 0 | G33: =$C33*G34 -> 0 | H33: =$C33*H34 -> 0 | I33: =$C33*I34 -> 0 | J33: =$C33*J34 -> 0 | K33: =$C33*K34 -> 0 | ... U33: =$C33*U34 -> 0
B34: Dedicación | C34: =SUM(D34:U34) -> 0 | D34: ='A cobrar'!D34 -> 0 | E34: ='A cobrar'!E34 -> 0 | F34: ='A cobrar'!F34 -> 0 | G34: ='A cobrar'!G34 -> 0 | H34: ='A cobrar'!H34 -> 0 | I34: ='A cobrar'!I34 -> 0 | J34: ='A cobrar'!J34 -> 0 | K34: ='A cobrar'!K34 -> 0 | ... U34: ='A cobrar'!U34 -> 0
C35: =SUM(D35:U35) -> 0 | D35: =D34*D33 -> 0 | E35: =E34*E33 -> 0 | F35: =F34*F33 -> 0 | G35: =G34*G33 -> 0 | H35: =H34*H33 -> 0 | I35: =I34*I33 -> 0 | J35: =J34*J33 -> 0 | K35: =K34*K33 -> 0 | ... U35: =U34*U33 -> 0
A36: ='A cobrar'!A36 -> Rol 12 | B36: Salario mensual | D36: =$C36*D37 -> 0 | E36: =$C36*E37 -> 0 | F36: =$C36*F37 -> 0 | G36: =$C36*G37 -> 0 | H36: =$C36*H37 -> 0 | I36: =$C36*I37 -> 0 | J36: =$C36*J37 -> 0 | K36: =$C36*K37 -> 0 | ... U36: =$C36*U37 -> 0
B37: Dedicación | C37: =SUM(D37:U37) -> 0 | D37: ='A cobrar'!D37 -> 0 | E37: ='A cobrar'!E37 -> 0 | F37: ='A cobrar'!F37 -> 0 | G37: ='A cobrar'!G37 -> 0 | H37: ='A cobrar'!H37 -> 0 | I37: ='A cobrar'!I37 -> 0 | J37: ='A cobrar'!J37 -> 0 | K37: ='A cobrar'!K37 -> 0 | ... U37: ='A cobrar'!U37 -> 0
C38: =SUM(D38:U38) -> 0 | D38: =D37*D36 -> 0 | E38: =E37*E36 -> 0 | F38: =F37*F36 -> 0 | G38: =G37*G36 -> 0 | H38: =H37*H36 -> 0 | I38: =I37*I36 -> 0 | J38: =J37*J36 -> 0 | K38: =K37*K36 -> 0 | ... U38: =U37*U36 -> 0
A39: ='A cobrar'!A39 -> Rol 13 | B39: Salario mensual | D39: =$C39*D40 -> 0 | E39: =$C39*E40 -> 0 | F39: =$C39*F40 -> 0 | G39: =$C39*G40 -> 0 | H39: =$C39*H40 -> 0 | I39: =$C39*I40 -> 0 | J39: =$C39*J40 -> 0 | K39: =$C39*K40 -> 0 | ... U39: =$C39*U40 -> 0
B40: Dedicación | C40: =SUM(D40:U40) -> 0 | D40: ='A cobrar'!D40 -> 0 | E40: ='A cobrar'!E40 -> 0 | F40: ='A cobrar'!F40 -> 0 | G40: ='A cobrar'!G40 -> 0 | H40: ='A cobrar'!H40 -> 0 | I40: ='A cobrar'!I40 -> 0 | J40: ='A cobrar'!J40 -> 0 | K40: ='A cobrar'!K40 -> 0 | ... U40: ='A cobrar'!U40 -> 0
...

Sheet Valores ejecutados
D1: Mes 1 | E1: Mes 2 | F1: Mes 3 | G1: Mes 4 | H1: Mes 5 | I1: Mes 6 | J1: Mes 7 | K1: Mes 8 | L1: Mes 9 | M1: Mes 10 | N1: Mes 11 | O1: Mes 12 | P1: Mes 13 | Q1: Mes 14 | R1: Mes 15 | S1: Mes 16 | T1: Mes 17 | U1: Mes 18
A2: Personal y rol ejecutado | B2: =+C6+C9+C12+C15+C18+C21+C24+C30+C27+C33+C36+C39+C42+C45+C48 -> 0 | C2: Totales | D2: =+D6+D9+D12+D15+D18+D21+D24+D30+D27+D33+D36+D39+D42+D45+D48 -> 0 | E2: =+E6+E9+E12+E15+E18+E21+E24+E30+E27+E33+E36+E39+E42+E45+E48 -> 0 | F2: =+F6+F9+F12+F15+F18+F21+F24+F30+F27+F33+F36+F39+F42+F45+F48 -> 0 | G2: =+G6+G9+G12+G15+G18+G21+G24+G30+G27+G33+G36+G39+G42+G45+G48 -> 0 | H2: =+H6+H9+H12+H15+H18+H21+H24+H30+H27+H33+H36+H39+H42+H45+H48 -> 0 | I2: =+I6+I9+I12+I15+I18+I21+I24+I30+I27+I33+I36+I39+I42+I45+I48 -> 0 | J2: =+J6+J9+J12+J15+J18+J21+J24+J30+J27+J33+J36+J39+J42+J45+J48 -> 0 | K2: =+K6+K9+K12+K15+K18+K21+K24+K30+K27+K33+K36+K39+K42+K45+K48 -> 0 | ... U2: =+U6+U9+U12+U15+U18+U21+U24+U30+U27+U33+U36+U39+U42+U45+U48 -> 0
D3: =+D5+D8+D11+D14+D17+D20+D23+D29+D26+D32+D35+D38+D41+D44+D47 -> 0 | E3: =+E5+E8+E11+E14+E17+E20+E23+E29+E26+E32+E35+E38+E41+E44+E47 -> 0 | F3: =+F5+F8+F11+F14+F17+F20+F23+F29+F26+F32+F35+F38+F41+F44+F47 -> 0 | G3: =+G5+G8+G11+G14+G17+G20+G23+G29+G26+G32+G35+G38+G41+G44+G47 -> 0 | H3: =+H5+H8+H11+H14+H17+H20+H23+H29+H26+H32+H35+H38+H41+H44+H47 -> 0 | I3: =+I5+I8+I11+I14+I17+I20+I23+I29+I26+I32+I35+I38+I41+I44+I47 -> 0 | J3: =+J5+J8+J11+J14+J17+J20+J23+J29+J26+J32+J35+J38+J41+J44+J47 -> 0 | K3: =+K5+K8+K11+K14+K17+K20+K23+K29+K26+K32+K35+K38+K41+K44+K47 -> 0 | ... U3: =+U5+U8+U11+U14+U17+U20+U23+U29+U26+U32+U35+U38+U41+U44+U47 -> 0
A4: Persona 1 | B4: Salario mensual
B5: Dedicación | C5: =SUM(D5:U5) -> 0
C6: =SUM(D6:U6) -> 0 | D6: =D5*D4 -> 0 | E6: =E5*E4 -> 0 | F6: =F5*F4 -> 0 | G6: =G5*G4 -> 0 | H6: =H5*H4 -> 0 | I6: =I5*I4 -> 0 | J6: =J5*J4 -> 0 | K6: =K5*K4 -> 0 | ... U6: =U5*U4 -> 0
A7: Persona 2 | B7: Salario mensual
B8: Dedicación | C8: =SUM(D8:U8) -> 0
C9: =SUM(D9:U9) -> 0 | D9: =D8*D7 -> 0 | E9: =E8*E7 -> 0 | F9: =F8*F7 -> 0 | G9: =G8*G7 -> 0 | H9: =H8*H7 -> 0 | I9: =I8*I7 -> 0 | J9: =J8*J7 -> 0 | K9: =K8*K7 -> 0 | ... U9: =U8*U7 -> 0
A10: Persona 3 | B10: Salario mensual
B11: Dedicación | C11: =SUM(D11:U11) -> 0
C12: =SUM(D12:U12) -> 0 | D12: =D11*D10 -> 0 | E12: =E11*E10 -> 0 | F12: =F11*F10 -> 0 | G12: =G11*G10 -> 0 | H12: =H11*H10 -> 0 | I12: =I11*I10 -> 0 | J12: =J11*J10 -> 0 | K12: =K11*K10 -> 0 | ... U12: =U11*U10 -> 0
A13: Persona 4 | B13: Salario mensual
B14: Dedicación | C14: =SUM(D14:U14) -> 0
C15: =SUM(D15:U15) -> 0 | D15: =D14*D13 -> 0 | E15: =E14*E13 -> 0 | F15: =F14*F13 -> 0 | G15: =G14*G13 -> 0 | H15: =H14*H13 -> 0 | I15: =I14*I13 -> 0 | J15: =J14*J13 -> 0 | K15: =K14*K13 -> 0 | ... U15: =U14*U13 -> 0
A16: Persona 5 | B16: Salario mensual
B17: Dedicación | C17: =SUM(D17:U17) -> 0
C18: =SUM(D18:U18) -> 0 | D18: =D17*D16 -> 0 | E18: =E17*E16 -> 0 | F18: =F17*F16 -> 0 | G18: =G17*G16 -> 0 | H18: =H17*H16 -> 0 | I18: =I17*I16 -> 0 | J18: =J17*J16 -> 0 | K18: =K17*K16 -> 0 | ... U18: =U17*U16 -> 0
A19: Persona 6 | B19: Salario mensual
B20: Dedicación | C20: =SUM(D20:U20) -> 0
C21: =SUM(D21:U21) -> 0 | D21: =D20*D19 -> 0 | E21: =E20*E19 -> 0 | F21: =F20*F19 -> 0 | G21: =G20*G19 -> 0 | H21: =H20*H19 -> 0 | I21: =I20*I19 -> 0 | J21: =J20*J19 -> 0 | K21: =K20*K19 -> 0 | ... U21: =U20*U19 -> 0
A22: Persona 7 | B22: Salario mensual
B23: Dedicación | C23: =SUM(D23:U23) -> 0
C24: =SUM(D24:U24) -> 0 | D24: =D23*D22 -> 0 | E24: =E23*E22 -> 0 | F24: =F23*F22 -> 0 | G24: =G23*G22 -> 0 | H24: =H23*H22 -> 0 | I24: =I23*I22 -> 0 | J24: =J23*J22 -> 0 | K24: =K23*K22 -> 0 | ... U24: =U23*U22 -> 0
A25: Persona 8 | B25: Salario mensual
B26: Dedicación | C26: =SUM(D26:U26) -> 0
C27: =SUM(D27:U27) -> 0 | D27: =D26*D25 -> 0 | E27: =E26*E25 -> 0 | F27: =F26*F25 -> 0 | G27: =G26*G25 -> 0 | H27: =H26*H25 -> 0 | I27: =I26*I25 -> 0 | J27: =J26*J25 -> 0 | K27: =K26*K25 -> 0 | ... U27: =U26*U25 -> 0
A28: Persona 9 | B28: Salario mensual
B29: Dedicación | C29: =SUM(D29:U29) -> 0
C30: =SUM(D30:U30) -> 0 | D30: =D29*D28 -> 0 | E30: =E29*E28 -> 0 | F30: =F29*F28 -> 0 | G30: =G29*G28 -> 0 | H30: =H29*H28 -> 0 | I30: =I29*I28 -> 0 | J30: =J29*J28 -> 0 | K30: =K29*K28 -> 0 | ... U30: =U29*U28 -> 0
A31: Persona 10 | B31: Salario mensual
B32: Dedicación | C32: =SUM(D32:U32) -> 0
C33: =SUM(D33:U33) -> 0 | D33: =D32*D31 -> 0 | E33: =E32*E31 -> 0 | F33: =F32*F31 -> 0 | G33: =G32*G31 -> 0 | H33: =H32*H31 -> 0 | I33: =I32*I31 -> 0 | J33: =J32*J31 -> 0 | K33: =K32*K31 -> 0 | ... U33: =U32*U31 -> 0
A34: Persona 11 | B34: Salario mensual
B35: Dedicación | C35: =SUM(D35:U35) -> 0
C36: =SUM(D36:U36) -> 0 | D36: =D35*D34 -> 0 | E36: =E35*E34 -> 0 | F36: =F35*F34 -> 0 | G36: =G35*G34 -> 0 | H36: =H35*H34 -> 0 | I36: =I35*I34 -> 0 | J36: =J35*J34 -> 0 | K36: =K35*K34 -> 0 | ... U36: =U35*U34 -> 0
A37: Persona 12 | B37: Salario mensual
B38: Dedicación | C38: =SUM(D38:U38) -> 0
C39: =SUM(D39:U39) -> 0 | D39: =D38*D37 -> 0 | E39: =E38*E37 -> 0 | F39: =F38*F37 -> 0 | G39: =G38*G37 -> 0 | H39: =H38*H37 -> 0 | I39: =I38*I37 -> 0 | J39: =J38*J37 -> 0 | K39: =K38*K37 -> 0 | ... U39: =U38*U37 -> 0
A40: Persona 13 | B40: Salario mensual
...

Sheet Caja planeada
C1: CAJA | D1: Mes 1 | E1: Mes 2 | F1: Mes 3 | G1: Mes 4 | H1: Mes 5 | I1: Mes 6 | J1: Mes 7 | K1: Mes 8 | L1: Mes 9 | M1: Mes 10 | N1: Mes 11 | O1: Mes 12 | P1: Mes 13 | Q1: Mes 14 | R1: Mes 15 | S1: Mes 16 | T1: Mes 17 | U1: Mes 18
C2: Mensual | D2: ='A cobrar'!D69-'Costos planeados'!D68 -> 8900000 | E2: ='A cobrar'!E69-'Costos planeados'!E68 -> 0 | F2: ='A cobrar'!F69-'Costos planeados'!F68 -> 0 | G2: ='A cobrar'!G69-'Costos planeados'!G68 -> 0 | H2: ='A cobrar'!H69-'Costos planeados'!H68 -> 0 | I2: ='A cobrar'!I69-'Costos planeados'!I68 -> 0 | J2: ='A cobrar'!J69-'Costos planeados'!J68 -> 0 | K2: ='A cobrar'!K69-'Costos planeados'!K68 -> 0 | ... U2: ='A cobrar'!U69-'Costos planeados'!U68 -> 0
C3: Acumulado | D3: =D2 -> 8900000 | E3: =D3+E2 -> 8900000 | F3: =E3+F2 -> 8900000 | G3: =F3+G2 -> 8900000 | H3: =G3+H2 -> 8900000 | I3: =H3+I2 -> 8900000 | J3: =I3+J2 -> 8900000 | K3: =J3+K2 -> 8900000 | L3: =K3+L2 -> 8900000 | ... U3: =T3+U2 -> 8900000
A4: Cobrado | B4: ='A cobrar'!B66:C66 -> 8900000
A5: Costos planeados | B5: ='Costos planeados'!B68 -> 192774
A6: Comisión comercial | B6: ='A cobrar'!C64 -> 0
A7: Utilidad neta $ | B7: =B4-B5-B6 -> 8707226 | D7: =IF(B7<0,"Este proyecto dá perdida!!!","")
A8: Utilidad neta % | B8: =B7/B5 -> 45.168052

Sheet Caja real
C1: CAJA | D1: Mes 1 | E1: Mes 2 | F1: Mes 3 | G1: Mes 4 | H1: Mes 5 | I1: Mes 6 | J1: Mes 7 | K1: Mes 8 | L1: Mes 9 | M1: Mes 10 | N1: Mes 11 | O1: Mes 12 | P1: Mes 13 | Q1: Mes 14 | R1: Mes 15 | S1: Mes 16 | T1: Mes 17 | U1: Mes 18
C2: Mes | D2: ='Valores ejecutados'!D75-'Valores ejecutados'!D70 -> 0 | E2: ='Valores ejecutados'!E75-'Valores ejecutados'!E70 -> 0 | F2: ='Valores ejecutados'!F75-'Valores ejecutados'!F70 -> 0 | G2: ='Valores ejecutados'!G75-'Valores ejecutados'!G70 -> 0 | H2: ='Valores ejecutados'!H75-'Valores ejecutados'!H70 -> 0 | I2: ='Valores ejecutados'!I75-'Valores ejecutados'!I70 -> 0 | J2: ='Valores ejecutados'!J75-'Valores ejecutados'!J70 -> 0 | K2: ='Valores ejecutados'!K75-'Valores ejecutados'!K70 -> 0 | ... U2: ='Valores ejecutados'!U75-'Valores ejecutados'!U70 -> 0
C3: Acumulado | D3: =D2 -> 0 | E3: =D3+E2 -> 0 | F3: =E3+F2 -> 0 | G3: =F3+G2 -> 0 | H3: =G3+H2 -> 0 | I3: =H3+I2 -> 0 | J3: =I3+J2 -> 0 | K3: =J3+K2 -> 0 | L3: =K3+L2 -> 0 | ... U3: =T3+U2 -> 0
A4: Cobrado | B4: ='A cobrar'!B66:C66 -> 8900000
A5: Costos ejecutados | B5: ='Valores ejecutados'!B70 -> 0
A6: Comisión comercial | B6: ='A cobrar'!C64 -> 0
A7: Utilidad neta $ | B7: =B4-B5-B6 -> 8900000 | D7: =IF(B7<0,"Este proyecto dá perdida!!!","")
A8: Utilidad neta % | B8: =B7/B5 -> #DIV/0!
D11: Comparativo entre planeado y ejecutado
D12: Mensual
D13: =D2-'Caja planeada'!D2 -> -8900000 | E13: =E2-'Caja planeada'!E2 -> 0 | F13: =F2-'Caja planeada'!F2 -> 0 | G13: =G2-'Caja planeada'!G2 -> 0 | H13: =H2-'Caja planeada'!H2 -> 0 | I13: =I2-'Caja planeada'!I2 -> 0 | J13: =J2-'Caja planeada'!J2 -> 0 | K13: =K2-'Caja planeada'!K2 -> 0 | ... U13: =U2-'Caja planeada'!U2 -> 0
D15: Acumulado
D16: =D3-'Caja planeada'!D3 -> -8900000 | E16: =E3-'Caja planeada'!E3 -> -8900000 | F16: =F3-'Caja planeada'!F3 -> -8900000 | G16: =G3-'Caja planeada'!G3 -> -8900000 | H16: =H3-'Caja planeada'!H3 -> -8900000 | I16: =I3-'Caja planeada'!I3 -> -8900000 | J16: =J3-'Caja planeada'!J3 -> -8900000 | K16: =K3-'Caja planeada'!K3 -> -8900000 | ... U16: =U3-'Caja planeada'!U3 -> -8900000
